PS E:\skripsi-kmeans-nlp-monev> python main.py
Traceback (most recent call last):
  File "C:\Users\syahr\AppData\Roaming\Python\Python312\site-packages\pandas\core\indexes\base.py", line 3805, in get_loc
    return self._engine.get_loc(casted_key)
           ^^^^^^^^^^^^^^^^^^^^^^^^^^^^^^^^
  File "index.pyx", line 167, in pandas._libs.index.IndexEngine.get_loc
  File "index.pyx", line 196, in pandas._libs.index.IndexEngine.get_loc
  File "pandas\\_libs\\hashtable_class_helper.pxi", line 7081, in pandas._libs.hashtable.PyObjectHashTable.get_item
  File "pandas\\_libs\\hashtable_class_helper.pxi", line 7089, in pandas._libs.hashtable.PyObjectHashTable.get_item
KeyError: 'teks_bersih'

The above exception was the direct cause of the following exception:

Traceback (most recent call last):
  File "E:\skripsi-kmeans-nlp-monev\main.py", line 77, in <module>
    main()
  File "E:\skripsi-kmeans-nlp-monev\main.py", line 31, in main
    tfidf_matrix, feature_names, vectorizer = tfidf_vectorizer.ubah_ke_tfidf(df["teks_bersih"])
                                                                             ~~^^^^^^^^^^^^^^^
  File "C:\Users\syahr\AppData\Roaming\Python\Python312\site-packages\pandas\core\frame.py", line 4102, in __getitem__
    indexer = self.columns.get_loc(key)
              ^^^^^^^^^^^^^^^^^^^^^^^^^
  File "C:\Users\syahr\AppData\Roaming\Python\Python312\site-packages\pandas\core\indexes\base.py", line 3812, in get_loc
    raise KeyError(key) from err
KeyError: 'teks_bersih'